Workbook
Name fiscal_risk_index: Plan2!$B$2:$V$1858
Name fiscal_risk_index_1: Plan2!$B$2:$V$1858
Name fiscal_risk_index_2: Plan2!$B$2:$V$1330
Name fiscal_risk_index_3: Plan2!$B$2:$V$1874

Sheet Plan2
A1: 1 | B1: 2 | C1: 3 | D1: 4 | E1: 5 | F1: 6 | G1: 7 | H1: 8 | I1: 9 | J1: 10 | K1: 11 | L1: 12 | M1: 13 | N1: 14 | O1: 15 | P1: 16 | Q1: 17 | R1: 18 | S1: 19 | T1: 20 | U1: 21 | V1: 22
B2: country_code | C2: country | D2: year | E2: gdp_per_capita | F2: real_gdp_growth | G2: inflation_rate | H2: compulsory_education_years | I2: population_65_plus_pct | J2: unemployment_rate | K2: government_expenditure_pct_gdp | L2: government_revenue_pct_gdp | M2: gdp_deflator_inflation | N2: age_dependency_ratio | O2: gross_capital_formation_pct_gdp | P2: total_reserves_months_imports | Q2: savings_pct_gdp | R2: exports_pct_gdp | S2: fiscal_balance_pct_gdp | T2: gross_debt_pct_gdp | U2: fiscal_risk_index | V2: fiscal_risk_index_100
A3: =C3&D3 -> Afghanistan2010 | B3: AFG | C3: Afghanistan | D3: 2010 | E3: 560.62151 | F3: 14.362441 | G3: 2.1785375 | H3: 9 | I3: 2.3066149 | J3: 7.809 | K3: 50.863005 | L3: 11.091949 | M3: 3.8146303 | N3: 103.14446 | O3: 14.146241 | P3: 10.457387 | Q3: -2.7377694 | R3: 15.59747 | S3: 0.93334363 | T3: 7.6969493 | U3: -0.57359519 | V3: 30.047967
A4: =C4&D4 -> Afghanistan2011 | B4: AFG | C4: Afghanistan | D4: 2011 | E4: 606.69468 | F4: 0.42635478 | G4: 11.804186 | H4: 9 | I4: 2.3221405 | J4: 7.83 | K4: 59.484776 | L4: 11.510161 | M4: 16.593347 | N4: 101.45831 | O4: 14.146241 | P4: 10.343973 | Q4: -2.7377694 | R4: 15.59747 | S4: -0.6718217 | T4: 7.5010844 | U4: -0.71217562 | V4: 27.391958
A5: =C5&D5 -> Afghanistan2012 | B5: AFG | C5: Afghanistan | D5: 2012 | E5: 651.41713 | F5: 12.752287 | G5: 6.4412128 | H5: 9 | I5: 2.3379113 | J5: 7.875 | K5: 42.329251 | L5: 10.200625 | M5: 7.3017565 | N5: 99.773131 | O5: 14.146241 | P5: 8.6772089 | Q5: -2.7377694 | R5: 15.59747 | S5: 0.18205705 | T5: 6.7594679 | U5: -0.68277398 | V5: 27.955465
A6: =C6&D6 -> Afghanistan2013 | B6: AFG | C6: Afghanistan | D6: 2013 | E6: 637.0871 | F6: 5.6007447 | G6: 7.3857718 | H6: 9 | I6: 2.349769 | J6: 7.921 | K6: 42.093684 | L6: 9.4056093 | M6: 4.8227855 | N6: 98.063559 | O6: 14.146241 | P6: 8.5881377 | Q6: -2.7377694 | R6: 15.59747 | S6: -0.63094557 | T6: 6.9044792 | U6: -0.79390637 | V6: 25.82552
A7: =C7&D7 -> Afghanistan2014 | B7: AFG | C7: Afghanistan | D7: 2014 | E7: 625.05494 | F7: 2.7245434 | G7: 4.673996 | H7: 9 | I7: 2.3565357 | J7: 7.915 | K7: 44.589299 | L7: 8.6137305 | M7: 0.56694454 | N7: 96.346394 | O7: 14.146241 | P7: 10.702695 | Q7: -2.7377694 | R7: 15.59747 | S7: -1.7187968 | T7: 8.700291 | U7: -0.83403838 | V7: 25.056357
A8: =C8&D8 -> Afghanistan2015 | B8: AFG | C8: Afghanistan | D8: 2015 | E8: 565.56973 | F8: 1.4513147 | G8: -0.66170916 | H8: 9 | I8: 2.3566951 | J8: 9.032 | K8: 37.02257 | L8: 10.131118 | M8: 2.447563 | N8: 94.613234 | O8: 14.146241 | P8: 9.770194 | Q8: -2.7377694 | R8: 15.59747 | S8: -1.3777003 | T8: 9.1540829 | U8: -0.88055329 | V8: 24.16486
A9: =C9&D9 -> Afghanistan2016 | B9: AFG | C9: Afghanistan | D9: 2016 | E9: 522.08222 | F9: 2.2603142 | G9: 4.383892 | H9: 9 | I9: 2.3554974 | J9: 10.116 | K9: 43.922766 | L9: 12.67801 | M9: -2.1975265 | N9: 92.889871 | O9: 14.146241 | P9: 11.82806 | Q9: -2.7377694 | R9: 15.59747 | S9: 0.12725798 | T9: 8.4372661 | U9: -0.71227606 | V9: 27.390033
A10: =C10&D10 -> Afghanistan2017 | B10: AFG | C10: Afghanistan | D10: 2017 | E10: 525.46977 | F10: 2.6470032 | G10: 4.9759515 | H10: 9 | I10: 2.359737 | J10: 11.184 | K10: 39.22011 | L10: 13.039262 | M10: 2.4036562 | N10: 91.293619 | O10: 14.146241 | P10: 12.134277 | Q10: -2.7377694 | R10: 15.59747 | S10: -0.67310591 | T10: 7.9976602 | U10: -0.77494343 | V10: 26.188961
A11: =C11&D11 -> Afghanistan2018 | B11: AFG | C11: Afghanistan | D11: 2018 | E11: 491.33722 | F11: 1.1892281 | G11: 0.62614915 | H11: 9 | I11: 2.3671205 | J11: 11.192 | K11: 43.126009 | L11: 10.646287 | M11: 2.0713486 | N11: 89.849606 | O11: 14.146241 | P11: 12.178587 | Q11: -2.7377694 | R11: 15.59747 | S11: 1.6341957 | T11: 7.3844129 | U11: -0.6788269 | V11: 28.031114
A12: =C12&D12 -> Afghanistan2019 | B12: AFG | C12: Afghanistan | D12: 2019 | E12: 496.6025 | F12: 3.9116034 | G12: 2.3023725 | H12: 9 | I12: 2.3761534 | J12: 11.187 | K12: 43.126009 | L12: 10.646287 | M12: 6.5214798 | N12: 88.512028 | O12: 14.146241 | P12: 13.748909 | Q12: -2.7377694 | R12: 15.59747 | S12: -1.0580811 | T12: 6.1363465 | U12: -0.73913597 | V12: 26.875241
A13: =C13&D13 -> Afghanistan2020 | B13: AFG | C13: Afghanistan | D13: 2020 | E13: 510.78706 | F13: -2.3511007 | G13: 5.6018879 | H13: 9 | I13: 2.3707338 | J13: 11.71 | K13: 43.126009 | L13: 10.646287 | M13: 6.9629463 | N13: 87.247817 | O13: 11.5 | P13: 16.631634 | Q13: -2.7377694 | R13: 10.420817 | S13: -2.2427994 | T13: 7.3311473 | U13: -0.82768331 | V13: 25.178157
A14: =C14&D14 -> Afghanistan2021 | B14: AFG | C14: Afghanistan | D14: 2021 | E14: 356.49621 | F14: -20.738839 | G14: 5.1332034 | H14: 9 | I14: 2.3525495 | J14: 12.006 | K14: 43.126009 | L14: 10.646287 | M14: 2.8389963 | N14: 86.083468 | O14: 13 | P14: 10.702695 | Q14: -2.7377694 | R14: 14.342153 | S14: -0.48493882 | T14: 11.135733 | U14: -1.0060648 | V14: 21.759328
... A1858: =C1858&D1858 -> Zambia2025 | B1858: ZMB | C1858: Zambia | D1858: 2025 | E1858: 1447.1231 | F1858: 4.6932832 | G1858: 9.1503164 | H1858: 7 | I1858: 1.7870091 | J1858: 5.918 | K1858: 20.589158 | L1858: 17.935035 | M1858: 9.7308912 | N1858: 86.088028 | O1858: 32.889211 | P1858: 3.1407366 | Q1858: 39.520359 | R1858: 38.82229 | S1858: -3.8343418 | T1858: 86.004375 | U1858: -0.94455314 | V1858: 22.93825
B1859: ZWE | C1859: Zimbabwe | D1859: 2010 | E1859: 902.01076 | F1859: 19.675408 | G1859: 3.02267 | H1859: 7 | I1859: 3.1021003 | J1859: 5.469 | K1859: 16.120944 | L1859: 19.407389 | M1859: 4.0976379 | N1859: 85.67068 | O1859: 18.76284 | P1859: 1.331807 | Q1859: 1.5068498 | R1859: 29.640389 | S1859: -0.39742684 | T1859: 33.184748 | U1859: -0.70120588 | V1859: 27.602202
B1860: ZWE | C1860: Zimbabwe | D1860: 2011 | E1860: 1037.7757 | F1860: 14.193916 | G1860: 3.4661297 | H1860: 7 | I1860: 3.0907569 | J1860: 5.368 | K1860: 19.077155 | L1860: 20.672979 | M1860: 2.5527525 | N1860: 86.798954 | O1860: 17.398469 | P1860: 0.83151411 | Q1860: 4.7782544 | R1860: 34.800482 | S1860: -1.9776681 | T1860: 30.017969 | U1860: -0.73042824 | V1860: 27.042131
B1861: ZWE | C1861: Zimbabwe | D1861: 2012 | E1861: 1239.2271 | F1861: 16.665429 | G1861: 3.7253267 | H1861: 7 | I1861: 3.0890034 | J1861: 5.057 | K1861: 20.21193 | L1861: 20.395154 | M1861: 4.0289277 | N1861: 87.859421 | O1861: 9.8563378 | P1861: 0.79538565 | Q1861: -6.750351 | R1861: 25.162788 | S1861: -0.35222546 | T1861: 27.172872 | U1861: -0.68229671 | V1861: 27.964612
B1862: ZWE | C1862: Zimbabwe | D1862: 2013 | E1862: 1362.995 | F1862: 1.9894855 | G1862: 1.6349504 | H1862: 7 | I1862: 3.0945799 | J1862: 4.948 | K1862: 19.077155 | L1862: 19.003463 | M1862: 9.3710751 | N1862: 88.637828 | O1862: 9.2090625 | P1862: 0.65623684 | Q1862: -0.49351388 | R1862: 21.987357 | S1862: -1.2109073 | T1862: 26.434453 | U1862: -0.85603553 | V1862: 24.634763
B1863: ZWE | C1863: Zimbabwe | D1863: 2014 | E1863: 1372.9153 | F1863: 2.3769856 | G1863: -0.19778481 | H1863: 7 | I1863: 3.1381062 | J1863: 4.774 | K1863: 19.077155 | L1863: 19.003463 | M1863: -0.2519696 | N1863: 88.927571 | O1863: 9.6395888 | P1863: 0.52842735 | Q1863: 1.5214395 | R1863: 20.929994 | S1863: -0.87223518 | T1863: 29.201709 | U1863: -0.83621317 | V1863: 25.014675
B1864: ZWE | C1864: Zimbabwe | D1864: 2015 | E1864: 1387.1263 | F1864: 1.7798536 | G1864: -2.4309684 | H1864: 7 | I1864: 3.2214916 | J1864: 5.399 | K1864: 21.809485 | L1864: 19.003463 | M1864: 0.60737758 | N1864: 88.836358 | O1864: 10.035923 | P1864: 0.68760471 | Q1864: -0.99101814 | R1864: 19.160627 | S1864: -1.6060112 | T1864: 34.094126 | U1864: -0.90812891 | V1864: 23.63635
B1865: ZWE | C1865: Zimbabwe | D1865: 2016 | E1865: 1408.1395 | F1865: 0.75579406 | G1865: -1.5436696 | H1865: 7 | I1865: 3.3057793 | J1865: 5.896 | K1865: 25.236248 | L1865: 17.194652 | M1865: 2.1617914 | N1865: 88.327528 | O1865: 9.8617411 | P1865: 0.74170695 | Q1865: -1.223528 | R1865: 19.943578 | S1865: -4.9932285 | T1865: 35.053719 | U1865: -1.0717546 | V1865: 20.500328
B1866: ZWE | C1866: Zimbabwe | D1866: 2017 | E1866: 3445.4494 | F1866: 4.7344112 | G1866: 0.89396232 | H1866: 7 | I1866: 3.3874573 | J1866: 6.35 | K1866: 9.7827666 | L1866: 5.9579059 | M1866: 197.45466 | N1866: 87.512352 | O1866: 14.702243 | P1866: 0.53101762 | Q1866: 8.4171705 | R1866: 24.658176 | S1866: -8.6761383 | T1866: 48.981461 | U1866: -1.3965554 | V1866: 14.275251
B1867: ZWE | C1867: Zimbabwe | D1867: 2018 | E1867: 2270.8953 | F1867: 5.0099215 | G1867: 10.618866 | H1867: 7 | I1867: 3.4651014 | J1867: 6.788 | K1867: 10.977284 | L1867: 8.1169583 | M1867: 3.5540556 | N1867: 86.51684 | O1867: 14.148444 | P1867: 0.13106298 | Q1867: 13.925526 | R1867: 26.164051 | S1867: -4.5514535 | T1867: 32.95732 | U1867: -1.1208353 | V1867: 19.559655
B1868: ZWE | C1868: Zimbabwe | D1868: 2019 | E1868: 2184.3292 | F1868: -6.3324498 | G1868: 255.30499 | H1868: 7 | I1868: 3.5342414 | J1868: 7.373 | K1868: 19.077155 | L1868: 19.003463 | M1868: 397.17374 | N1868: 85.447906 | O1868: 11.561629 | P1868: 0.31549509 | Q1868: 46.141645 | R1868: 22.769164 | S1868: -0.055606467 | T1868: 53.888867 | U1868: -0.65297121 | V1868: 28.52666
B1869: ZWE | C1869: Zimbabwe | D1869: 2020 | E1869: 2059.6745 | F1869: -7.8169506 | G1869: 557.20182 | H1869: 7 | I1869: 3.5816738 | J1869: 8.617 | K1869: 19.077155 | L1869: 19.003463 | M1869: 585.97283 | N1869: 84.384381 | O1869: 11.213924 | P1869: 0.06275633 | Q1869: 44.014632 | R1869: 18.931225 | S1869: 0.53090683 | T1869: 56.811099 | U1869: -0.7929634 | V1869: 25.843593
B1870: ZWE | C1870: Zimbabwe | D1870: 2021 | E1870: 2613.6054 | F1870: 8.4680168 | G1870: 98.546105 | H1870: 7 | I1870: 3.5979739 | J1870: 9.54 | K1870: 19.077155 | L1870: 19.003463 | M1870: 108.77282 | N1870: 83.384953 | O1870: 13.456563 | P1870: 1.14822 | Q1870: 42.874299 | R1870: 19.759617 | S1870: -1.8275391 | T1870: 39.891271 | U1870: -0.59483332 | V1870: 29.640921
... B1874: ZWE | C1874: Zimbabwe | D1874: 2025 | E1874: 2059.6745 | F1874: 4.7344112 | G1874: 3.4661297 | H1874: 7 | I1874: 3.3874573 | J1874: 9.293 | K1874: 19.077155 | L1874: 19.003463 | M1874: 9.3710751 | N1874: 86.51684 | O1874: 11.213924 | P1874: 0.65623684 | Q1874: 8.4171705 | R1874: 21.987357 | S1874: 0.081811674 | T1874: 43.76549 | U1874: -0.8212355 | V1874: 25.301735

Sheet Plan3
A1: country | B1: 2010 | C1: 2011 | D1: 2012 | E1: 2013 | F1: 2014 | G1: 2015 | H1: 2016 | I1: 2017 | J1: 2018 | K1: 2019 | L1: 2020 | M1: 2021 | N1: 2022 | O1: 2023 | P1: 2024 | Q1: 2025 | R1: S&P | S1: Moody's
A2: Macao SAR, China | B2: =VLOOKUP($A2&B$1,Plan2!$A:$V,22,FALSE) -> 92.616705 | C2: =VLOOKUP($A2&C$1,Plan2!$A:$V,22,FALSE) -> 100 | D2: =VLOOKUP($A2&D$1,Plan2!$A:$V,22,FALSE) -> 95.560441 | E2: =VLOOKUP($A2&E$1,Plan2!$A:$V,22,FALSE) -> 99.791282 | F2: =VLOOKUP($A2&F$1,Plan2!$A:$V,22,FALSE) -> 93.137122 | G2: =VLOOKUP($A2&G$1,Plan2!$A:$V,22,FALSE) -> 74.678615 | H2: =VLOOKUP($A2&H$1,Plan2!$A:$V,22,FALSE) -> 77.05189 | I2: =VLOOKUP($A2&I$1,Plan2!$A:$V,22,FALSE) -> 83.370654 | ... Q2: =VLOOKUP($A2&Q$1,Plan2!$A:$V,22,FALSE) -> 74.875615 | R2: =VLOOKUP(A2,ratings!A:E,3,FALSE) -> 0 | S2: =VLOOKUP(A2,ratings!A:E,4,FALSE) -> Aa3
A3: Luxembourg | B3: =VLOOKUP($A3&B$1,Plan2!$A:$V,22,FALSE) -> 80.77755 | C3: =VLOOKUP($A3&C$1,Plan2!$A:$V,22,FALSE) -> 82.696486 | D3: =VLOOKUP($A3&D$1,Plan2!$A:$V,22,FALSE) -> 83.218653 | E3: =VLOOKUP($A3&E$1,Plan2!$A:$V,22,FALSE) -> 84.632454 | F3: =VLOOKUP($A3&F$1,Plan2!$A:$V,22,FALSE) -> 86.118597 | G3: =VLOOKUP($A3&G$1,Plan2!$A:$V,22,FALSE) -> 82.586061 | H3: =VLOOKUP($A3&H$1,Plan2!$A:$V,22,FALSE) -> 84.428761 | I3: =VLOOKUP($A3&I$1,Plan2!$A:$V,22,FALSE) -> 84.69422 | ... Q3: =VLOOKUP($A3&Q$1,Plan2!$A:$V,22,FALSE) -> 83.053516 | R3: =VLOOKUP(A3,ratings!A:E,3,FALSE) -> AAA | S3: =VLOOKUP(A3,ratings!A:E,4,FALSE) -> Aaa
A4: Norway | B4: =VLOOKUP($A4&B$1,Plan2!$A:$V,22,FALSE) -> 76.54562 | C4: =VLOOKUP($A4&C$1,Plan2!$A:$V,22,FALSE) -> 82.075779 | D4: =VLOOKUP($A4&D$1,Plan2!$A:$V,22,FALSE) -> 82.780199 | E4: =VLOOKUP($A4&E$1,Plan2!$A:$V,22,FALSE) -> 79.047885 | F4: =VLOOKUP($A4&F$1,Plan2!$A:$V,22,FALSE) -> 77.031216 | G4: =VLOOKUP($A4&G$1,Plan2!$A:$V,22,FALSE) -> 70.487352 | H4: =VLOOKUP($A4&H$1,Plan2!$A:$V,22,FALSE) -> 67.204428 | I4: =VLOOKUP($A4&I$1,Plan2!$A:$V,22,FALSE) -> 69.435183 | ... Q4: =VLOOKUP($A4&Q$1,Plan2!$A:$V,22,FALSE) -> 75.310231 | R4: =VLOOKUP(A4,ratings!A:E,3,FALSE) -> AAA | S4: =VLOOKUP(A4,ratings!A:E,4,FALSE) -> Aaa
A5: Denmark | B5: =VLOOKUP($A5&B$1,Plan2!$A:$V,22,FALSE) -> 58.70359 | C5: =VLOOKUP($A5&C$1,Plan2!$A:$V,22,FALSE) -> 60.151027 | D5: =VLOOKUP($A5&D$1,Plan2!$A:$V,22,FALSE) -> 58.662672 | E5: =VLOOKUP($A5&E$1,Plan2!$A:$V,22,FALSE) -> 61.413686 | F5: =VLOOKUP($A5&F$1,Plan2!$A:$V,22,FALSE) -> 64.266744 | G5: =VLOOKUP($A5&G$1,Plan2!$A:$V,22,FALSE) -> 60.66972 | H5: =VLOOKUP($A5&H$1,Plan2!$A:$V,22,FALSE) -> 61.544705 | I5: =VLOOKUP($A5&I$1,Plan2!$A:$V,22,FALSE) -> 63.465709 | ... Q5: =VLOOKUP($A5&Q$1,Plan2!$A:$V,22,FALSE) -> 65.868169 | R5: =VLOOKUP(A5,ratings!A:E,3,FALSE) -> AAA | S5: =VLOOKUP(A5,ratings!A:E,4,FALSE) -> Aaa
A6: Netherlands | B6: =VLOOKUP($A6&B$1,Plan2!$A:$V,22,FALSE) -> 59.36913 | C6: =VLOOKUP($A6&C$1,Plan2!$A:$V,22,FALSE) -> 61.191438 | D6: =VLOOKUP($A6&D$1,Plan2!$A:$V,22,FALSE) -> 60.683961 | E6: =VLOOKUP($A6&E$1,Plan2!$A:$V,22,FALSE) -> 61.901496 | F6: =VLOOKUP($A6&F$1,Plan2!$A:$V,22,FALSE) -> 63.126611 | G6: =VLOOKUP($A6&G$1,Plan2!$A:$V,22,FALSE) -> 61.758298 | H6: =VLOOKUP($A6&H$1,Plan2!$A:$V,22,FALSE) -> 64.575795 | I6: =VLOOKUP($A6&I$1,Plan2!$A:$V,22,FALSE) -> 67.163249 | ... Q6: =VLOOKUP($A6&Q$1,Plan2!$A:$V,22,FALSE) -> 65.837348 | R6: =VLOOKUP(A6,ratings!A:E,3,FALSE) -> AAA | S6: =VLOOKUP(A6,ratings!A:E,4,FALSE) -> Aaa
A7: Switzerland | B7: =VLOOKUP($A7&B$1,Plan2!$A:$V,22,FALSE) -> 61.236679 | C7: =VLOOKUP($A7&C$1,Plan2!$A:$V,22,FALSE) -> 62.625862 | D7: =VLOOKUP($A7&D$1,Plan2!$A:$V,22,FALSE) -> 62.819192 | E7: =VLOOKUP($A7&E$1,Plan2!$A:$V,22,FALSE) -> 63.119044 | F7: =VLOOKUP($A7&F$1,Plan2!$A:$V,22,FALSE) -> 62.551071 | G7: =VLOOKUP($A7&G$1,Plan2!$A:$V,22,FALSE) -> 63.190752 | H7: =VLOOKUP($A7&H$1,Plan2!$A:$V,22,FALSE) -> 62.843862 | I7: =VLOOKUP($A7&I$1,Plan2!$A:$V,22,FALSE) -> 63.591287 | ... Q7: =VLOOKUP($A7&Q$1,Plan2!$A:$V,22,FALSE) -> 63.308592 | R7: =VLOOKUP(A7,ratings!A:E,3,FALSE) -> AAA | S7: =VLOOKUP(A7,ratings!A:E,4,FALSE) -> Aaa
A8: United Arab Emirates | B8: =VLOOKUP($A8&B$1,Plan2!$A:$V,22,FALSE) -> 43.819081 | C8: =VLOOKUP($A8&C$1,Plan2!$A:$V,22,FALSE) -> 51.272191 | D8: =VLOOKUP($A8&D$1,Plan2!$A:$V,22,FALSE) -> 61.325641 | E8: =VLOOKUP($A8&E$1,Plan2!$A:$V,22,FALSE) -> 61.595148 | F8: =VLOOKUP($A8&F$1,Plan2!$A:$V,22,FALSE) -> 55.973369 | G8: =VLOOKUP($A8&G$1,Plan2!$A:$V,22,FALSE) -> 48.488182 | H8: =VLOOKUP($A8&H$1,Plan2!$A:$V,22,FALSE) -> 51.02723 | I8: =VLOOKUP($A8&I$1,Plan2!$A:$V,22,FALSE) -> 51.741748 | ... Q8: =VLOOKUP($A8&Q$1,Plan2!$A:$V,22,FALSE) -> 56.877215 | R8: =VLOOKUP(A8,ratings!A:E,3,FALSE) -> AA | S8: =VLOOKUP(A8,ratings!A:E,4,FALSE) -> Aa2
A9: Austria | B9: =VLOOKUP($A9&B$1,Plan2!$A:$V,22,FALSE) -> 55.259763 | C9: =VLOOKUP($A9&C$1,Plan2!$A:$V,22,FALSE) -> 58.93195 | D9: =VLOOKUP($A9&D$1,Plan2!$A:$V,22,FALSE) -> 58.535659 | E9: =VLOOKUP($A9&E$1,Plan2!$A:$V,22,FALSE) -> 59.008392 | F9: =VLOOKUP($A9&F$1,Plan2!$A:$V,22,FALSE) -> 59.351053 | G9: =VLOOKUP($A9&G$1,Plan2!$A:$V,22,FALSE) -> 59.243987 | H9: =VLOOKUP($A9&H$1,Plan2!$A:$V,22,FALSE) -> 58.330934 | I9: =VLOOKUP($A9&I$1,Plan2!$A:$V,22,FALSE) -> 62.474384 | ... Q9: =VLOOKUP($A9&Q$1,Plan2!$A:$V,22,FALSE) -> 60.042605 | R9: =VLOOKUP(A9,ratings!A:E,3,FALSE) -> AA+ | S9: =VLOOKUP(A9,ratings!A:E,4,FALSE) -> Aa1
A10: Germany | B10: =VLOOKUP($A10&B$1,Plan2!$A:$V,22,FALSE) -> 52.494596 | C10: =VLOOKUP($A10&C$1,Plan2!$A:$V,22,FALSE) -> 56.832025 | D10: =VLOOKUP($A10&D$1,Plan2!$A:$V,22,FALSE) -> 56.991535 | E10: =VLOOKUP($A10&E$1,Plan2!$A:$V,22,FALSE) -> 57.535769 | F10: =VLOOKUP($A10&F$1,Plan2!$A:$V,22,FALSE) -> 58.982818 | G10: =VLOOKUP($A10&G$1,Plan2!$A:$V,22,FALSE) -> 58.449455 | H10: =VLOOKUP($A10&H$1,Plan2!$A:$V,22,FALSE) -> 59.23987 | I10: =VLOOKUP($A10&I$1,Plan2!$A:$V,22,FALSE) -> 60.144725 | ... Q10: =VLOOKUP($A10&Q$1,Plan2!$A:$V,22,FALSE) -> 56.728895 | R10: =VLOOKUP(A10,ratings!A:E,3,FALSE) -> AAA | S10: =VLOOKUP(A10,ratings!A:E,4,FALSE) -> Aaa
A11: Malta | B11: =VLOOKUP($A11&B$1,Plan2!$A:$V,22,FALSE) -> 55.265668 | C11: =VLOOKUP($A11&C$1,Plan2!$A:$V,22,FALSE) -> 55.675276 | D11: =VLOOKUP($A11&D$1,Plan2!$A:$V,22,FALSE) -> 56.264128 | E11: =VLOOKUP($A11&E$1,Plan2!$A:$V,22,FALSE) -> 58.285867 | F11: =VLOOKUP($A11&F$1,Plan2!$A:$V,22,FALSE) -> 60.647569 | G11: =VLOOKUP($A11&G$1,Plan2!$A:$V,22,FALSE) -> 61.088923 | H11: =VLOOKUP($A11&H$1,Plan2!$A:$V,22,FALSE) -> 62.111126 | I11: =VLOOKUP($A11&I$1,Plan2!$A:$V,22,FALSE) -> 69.19434 | ... Q11: =VLOOKUP($A11&Q$1,Plan2!$A:$V,22,FALSE) -> 62.196433 | R11: =VLOOKUP(A11,ratings!A:E,3,FALSE) -> A- | S11: =VLOOKUP(A11,ratings!A:E,4,FALSE) -> A2
A12: Cyprus | B12: =VLOOKUP($A12&B$1,Plan2!$A:$V,22,FALSE) -> 48.327286 | C12: =VLOOKUP($A12&C$1,Plan2!$A:$V,22,FALSE) -> 48.260788 | D12: =VLOOKUP($A12&D$1,Plan2!$A:$V,22,FALSE) -> 46.350722 | E12: =VLOOKUP($A12&E$1,Plan2!$A:$V,22,FALSE) -> 43.473898 | F12: =VLOOKUP($A12&F$1,Plan2!$A:$V,22,FALSE) -> 42.206426 | G12: =VLOOKUP($A12&G$1,Plan2!$A:$V,22,FALSE) -> 49.441152 | H12: =VLOOKUP($A12&H$1,Plan2!$A:$V,22,FALSE) -> 50.649866 | I12: =VLOOKUP($A12&I$1,Plan2!$A:$V,22,FALSE) -> 53.277723 | ... Q12: =VLOOKUP($A12&Q$1,Plan2!$A:$V,22,FALSE) -> 58.776515 | R12: =VLOOKUP(A12,ratings!A:E,3,FALSE) -> A- | S12: =VLOOKUP(A12,ratings!A:E,4,FALSE) -> A3
A13: Belgium | B13: =VLOOKUP($A13&B$1,Plan2!$A:$V,22,FALSE) -> 55.92754 | C13: =VLOOKUP($A13&C$1,Plan2!$A:$V,22,FALSE) -> 56.45722 | D13: =VLOOKUP($A13&D$1,Plan2!$A:$V,22,FALSE) -> 56.306206 | E13: =VLOOKUP($A13&E$1,Plan2!$A:$V,22,FALSE) -> 57.375797 | F13: =VLOOKUP($A13&F$1,Plan2!$A:$V,22,FALSE) -> 57.567677 | G13: =VLOOKUP($A13&G$1,Plan2!$A:$V,22,FALSE) -> 55.998634 | H13: =VLOOKUP($A13&H$1,Plan2!$A:$V,22,FALSE) -> 55.710335 | I13: =VLOOKUP($A13&I$1,Plan2!$A:$V,22,FALSE) -> 58.281292 | ... Q13: =VLOOKUP($A13&Q$1,Plan2!$A:$V,22,FALSE) -> 56.257727 | R13: =VLOOKUP(A13,ratings!A:E,3,FALSE) -> AA- | S13: =VLOOKUP(A13,ratings!A:E,4,FALSE) -> A1
... A115: Sudan | B115: =VLOOKUP($A115&B$1,Plan2!$A:$V,22,FALSE) -> 19.722608 | C115: =VLOOKUP($A115&C$1,Plan2!$A:$V,22,FALSE) -> 13.781343 | D115: =VLOOKUP($A115&D$1,Plan2!$A:$V,22,FALSE) -> 1.7214723 | E115: =VLOOKUP($A115&E$1,Plan2!$A:$V,22,FALSE) -> 8.7513111 | F115: =VLOOKUP($A115&F$1,Plan2!$A:$V,22,FALSE) -> 12.052422 | G115: =VLOOKUP($A115&G$1,Plan2!$A:$V,22,FALSE) -> 12.464205 | H115: =VLOOKUP($A115&H$1,Plan2!$A:$V,22,FALSE) -> 12.684324 | I115: =VLOOKUP($A115&I$1,Plan2!$A:$V,22,FALSE) -> 9.3042217 | ... Q115: =VLOOKUP($A115&Q$1,Plan2!$A:$V,22,FALSE) -> 9.1457442 | R115: =VLOOKUP(A115,ratings!A:E,3,FALSE) -> #N/A | S115: =VLOOKUP(A115,ratings!A:E,4,FALSE) -> #N/A

Sheet ratings
B1: S&P | C1: Moody's | D1: DBRS | E1: TE
A2: Australia | B2: Austrália | C2: AAA | D2: Aaa | E2: AAA
A3: Canada | B3: Canadá | C3: AAA | D3: Aaa | E3: AAA
A4: Denmark | B4: Dinamarca | C4: AAA | D4: Aaa | E4: AAA
A5: Germany | B5: Alemanha | C5: AAA | D5: Aaa | E5: AAA
B6: Liechtenstein | C6: AAA
A7: Luxembourg | B7: Luxemburgo | C7: AAA | D7: Aaa | E7: AAA
A8: Netherlands | B8: Holanda | C8: AAA | D8: Aaa | E8: AAA
A9: Norway | B9: Noruega | C9: AAA | D9: Aaa | E9: AAA
A10: Switzerland | B10: Suíça | C10: AAA | D10: Aaa | E10: AAA
A11: Sweden | B11: Suécia | C11: AAA | D11: Aaa | E11: AAA
B12: Cingapura | C12: AAA | D12: Aaa | E12: AAA
B13: União Europeia | C13: AA+ | D13: Aaa | E13: AAA
A14: New Zealand | B14: Nova Zelândia | C14: AA+ | D14: Aaa | E14: AAA
A15: United States | B15: Estados Unidos | C15: AA+ | D15: Aa1 | E15: AAA
A16: Austria | B16: Áustria | C16: AA+ | D16: Aa1 | E16: AAA
A17: Finland | B17: Finlândia | C17: AA+ | D17: Aa1 | E17: AA (high)
B18: Taiwan | C18: AA+ | D18: Aa3
A19: United Arab Emirates | B19: Emirados Árabes Unidos | C19: AA | D19: Aa2
B20: Hong Kong | C20: AA+ | D20: Aa3
A21: Ireland | B21: Irlanda | C21: AA+ | D21: Aa3 | E21: AA
B22: Catar | C22: AA | D22: Aa2
B23: Ilha do Homem | C23: N/A | D23: Aa3
A24: Macao SAR, China | B24: Macau | D24: Aa3
A25: United Kingdom | B25: Reino Unido | C25: AA | D25: Aa3 | E25: AA
A26: Korea, Rep. | B26: Coréia Do Sul | C26: AA | D26: Aa2
A27: Belgium | B27: Bélgica | C27: AA- | D27: A1 | E27: AA
B28: Ilhas Caimã | D28: Aa3
A29: Czechia | B29: República Tcheca | C29: AA- | D29: Aa3 | E29: AA
A30: France | B30: França | C30: A+ | D30: Aa3 | E30: AA
B31: Kuweit | C31: AA- | D31: A1
A32: Estonia | B32: Estônia | C32: NR | D32: A1 | E32: AA (low)
A33: Iceland | B33: Islândia | C33: A+ | D33: A1
A34: Saudi Arabia | B34: Arábia Saudita | C34: A+ | D34: Aa3
A35: Slovenia | B35: Eslovenia | C35: AA | D35: A2 | E35: AA (low)
B36: Bermudas | C36: A+ | D36: A1 | E36: A (high)
A37: China | B37: China | C37: A+ | D37: A1 | E37: A
A38: Japan | B38: Japão | C38: A+ | D38: A1 | E38: A (high)
A39: Lithuania | B39: Lituânia | C39: A | D39: A2 | E39: A (high)
A40: Malta | B40: Malta | C40: A- | D40: A2 | E40: A (high)
...
